06-06-2023 11:45:23 ERROR [sqlite_storage_engine:sqlite_storage_engine.py:_try_loading_table_via_reflection:0082] No table found with name FeatTablePPText
NoneType: None
06-06-2023 11:45:23 ERROR [sqlite_storage_engine:sqlite_storage_engine.py:drop:0119] Failed to drop the table FeatTablePPText with Exception No table found with name FeatTablePPText
Traceback (most recent call last):
  File "/data/jiashenc/workspace/eva/eva/storage/sqlite_storage_engine.py", line 110, in drop
    table_to_remove = self._try_loading_table_via_reflection(table.name)
  File "/data/jiashenc/workspace/eva/eva/storage/sqlite_storage_engine.py", line 83, in _try_loading_table_via_reflection
    raise Exception(err_msg)
Exception: No table found with name FeatTablePPText
06-06-2023 11:45:23 ERROR [plan_executor:plan_executor.py:execute_plan:0177] Failed to drop the table FeatTablePPText with Exception No table found with name FeatTablePPText
Traceback (most recent call last):
  File "/data/jiashenc/workspace/eva/eva/storage/sqlite_storage_engine.py", line 110, in drop
    table_to_remove = self._try_loading_table_via_reflection(table.name)
  File "/data/jiashenc/workspace/eva/eva/storage/sqlite_storage_engine.py", line 83, in _try_loading_table_via_reflection
    raise Exception(err_msg)
Exception: No table found with name FeatTablePPText

During handling of the above exception, another exception occurred:

Traceback (most recent call last):
  File "/data/jiashenc/workspace/eva/eva/executor/plan_executor.py", line 174, in execute_plan
    yield from output
  File "/data/jiashenc/workspace/eva/eva/executor/drop_executor.py", line 57, in exec
    storage_engine.drop(table=table_obj)
  File "/data/jiashenc/workspace/eva/eva/storage/sqlite_storage_engine.py", line 120, in drop
    raise Exception(err_msg)
Exception: Failed to drop the table FeatTablePPText with Exception No table found with name FeatTablePPText
06-06-2023 11:45:42 ERROR [executor_utils:executor_utils.py:handle_if_not_exists:0061] Table: FeatTablePPText already exists
06-06-2023 11:45:42 ERROR [plan_executor:plan_executor.py:execute_plan:0177] Table: FeatTablePPText already exists
Traceback (most recent call last):
  File "/data/jiashenc/workspace/eva/eva/executor/plan_executor.py", line 172, in execute_plan
    output = execution_tree.exec()
  File "/data/jiashenc/workspace/eva/eva/executor/create_executor.py", line 29, in exec
    if not handle_if_not_exists(self.node.table_info, self.node.if_not_exists):
  File "/data/jiashenc/workspace/eva/eva/executor/executor_utils.py", line 62, in handle_if_not_exists
    raise ExecutorError(err_msg)
eva.executor.executor_utils.ExecutorError: Table: FeatTablePPText already exists
Traceback (most recent call last):
  File "/data/jiashenc/workspace/eva/eva/executor/plan_executor.py", line 172, in execute_plan
    output = execution_tree.exec()
  File "/data/jiashenc/workspace/eva/eva/executor/create_executor.py", line 29, in exec
    if not handle_if_not_exists(self.node.table_info, self.node.if_not_exists):
  File "/data/jiashenc/workspace/eva/eva/executor/executor_utils.py", line 62, in handle_if_not_exists
    raise ExecutorError(err_msg)
eva.executor.executor_utils.ExecutorError: Table: FeatTablePPText already exists

During handling of the above exception, another exception occurred:

Traceback (most recent call last):
  File "evadb_qa.py", line 54, in <module>
    main()
  File "evadb_qa.py", line 50, in main
    ask_question(path)
  File "evadb_qa.py", line 32, in ask_question
    conn.query("""CREATE TABLE FeatTablePPText AS
  File "/data/jiashenc/workspace/eva/eva/interfaces/relational/relation.py", line 115, in execute
    result = execute_statement(self._query_node.copy())
  File "/data/jiashenc/workspace/eva/eva/interfaces/relational/utils.py", line 60, in execute_statement
    batch_list = list(output)
  File "/data/jiashenc/workspace/eva/eva/executor/plan_executor.py", line 178, in execute_plan
    raise ExecutorError(e)
eva.executor.executor_utils.ExecutorError: Table: FeatTablePPText already exists
